Workbook

Sheet PM POP RJBT
A1: NO | B1: KATEGORI | C1: POP NAME | D1: POP ID | E1: WILAYAH | F1: KP | G1: TIKOR | H1: SERVO | I1: PT.SERVO | J1: Tahap 1 | K1: Tahap 2 | L1: Tahap 3 | M1: Tahap 4 | N1: Tahap 5 | O1: Tahap 6 | P1: Persentase | Q1: STATUS | R1: HEALTH INDEX | S1: Catatan Hasil PM | T1: DONE | U1: MITRA | V1: PIC PM SERVO | W1: WO | X1: LAPORAN | Y1: LINK BA TAHAP 1 | Z1: TAHAP 2 | AA1: TAHAP 3 | AB1: TAHAP 4
A2: 1 | B2: POP-SB | C2: POP_1SBY003_INTILAND LT.5 | D2: POP_1SBY003 | E2: SURABAYA | F2: SURABAYA | G2: -7.27294566762687, 112.742837642641 | H2: SURABAYA | I2: PT. ALMAHYRA DIAN KURNIA | J2: 46079 | K2: 46173 | L2: 46209 | M2: 46302 | P2: =IF(B2="POP-SB",COUNTA(J2:M2)/4, IF(B2="POP-B",COUNTA(J2:M2)/2, COUNTA(J2:M2)/1)) -> 1 | Q2: =IF(P2=100%,"SELESAI","BELUM") -> SELESAI | T2: TRUE | U2: ALMAHYRA DIAN KURNIA | W2: WP142026024838 WP142026070982 | X2: TRUE | Y2: PM FOT POP_1SBY003_INTILAND LT.5.pdf | Z2: PM FOT POP_1SBY00003_INTILAND LT.5 TAHAP 2.pdf
A3: 2 | B3: POP-SB | C3: POP_1SDA002_WARU GI SHELTER-1 PLN | D3: POP_1SDA002 | E3: SURABAYA | F3: SURABAYA | G3: -7.347475646583534, 112.70742192864394 | H3: SIDOARJO | I3: PT. ALMAHYRA DIAN KURNIA | J3: 46079 | K3: 46149 | L3: 46247 | P3: =IF(B3="POP-SB",COUNTA(J3:M3)/4, IF(B3="POP-B",COUNTA(J3:M3)/2, COUNTA(J3:M3)/1)) -> 0.75 | Q3: =IF(P3=100%,"SELESAI","BELUM") -> BELUM | T3: FALSE | U3: ALMAHYRA DIAN KURNIA | W3: WP142026024849,WP142026050931 | X3: TRUE | Y3: PM FOT POP Shelter 1 GI Waru.docx
A4: 3 | B4: POP-B | C4: POP_1BJN001_BABAT GI SHELTER PLN | D4: POP_1BJN001 | E4: MADIUN | F4: MADIUN | G4: -7.12371918710264, 112.146650999529 | H4: TUBAN | I4: PT. INFRATECH INDONESIA | J4: 46149 | K4: 46269 | P4: =IF(B4="POP-SB",COUNTA(J4:M4)/4, IF(B4="POP-B",COUNTA(J4:M4)/2, COUNTA(J4:M4)/1)) -> 1 | Q4: =IF(P4=100%,"SELESAI","BELUM") -> SELESAI | T4: TRUE | U4: INFRATECH | W4: WP142026091147 | X4: TRUE | Y4: WP142026050951 PM POP SHELTER GI BABAT.pdf
A5: 4 | B5: POP-B | C5: POP_1KDR10048_BANARAN GI 2 SHELTER PLN | D5: POP_1KDR10048 | E5: MALANG | F5: MALANG | G5: -7.836792363410147, 112.03212950643739 | H5: KEDIRI | I5: PT. INFRATECH INDONESIA | J5: 46079 | K5: 46272 | P5: =IF(B5="POP-SB",COUNTA(J5:M5)/4, IF(B5="POP-B",COUNTA(J5:M5)/2, COUNTA(J5:M5)/1)) -> 1 | Q5: =IF(P5=100%,"SELESAI","BELUM") -> SELESAI | S5: Overload | T5: TRUE | U5: ADYWIANSA | W5: WP142026024894 | X5: TRUE
A6: 5 | B6: POP-B | C6: POP_1KDR002_BANARAN GI SHELTER PLN | D6: POP_1KDR002 | E6: MALANG | F6: MALANG | G6: -7.83650222429292, 112.031950078219 | H6: KEDIRI | I6: PT. INFRATECH INDONESIA | J6: 46079 | K6: 46204 | P6: =IF(B6="POP-SB",COUNTA(J6:M6)/4, IF(B6="POP-B",COUNTA(J6:M6)/2, COUNTA(J6:M6)/1)) -> 1 | Q6: =IF(P6=100%,"SELESAI","BELUM") -> SELESAI | S6: Genset Gagal nyaka | T6: TRUE | U6: ADYWIANSA | W6: WP142026024894 WP142026070186 | X6: TRUE | Y6: WP142026024894, WP142026024901 PM POP SHELTER GI BANARAN PLN.pdf
A7: 7 | B7: POP-B | C7: POP_1BKL002_BANGKALAN GI SHELTER PLN | D7: POP_1BKL002 | E7: SURABAYA | F7: SURABAYA | G7: -7.05720731558934, 112.79288184731 | H7: MADURA | I7: PT. ALMAHYRA DIAN KURNIA | J7: 46079 | K7: 46268 | P7: =IF(B7="POP-SB",COUNTA(J7:M7)/4, IF(B7="POP-B",COUNTA(J7:M7)/2, COUNTA(J7:M7)/1)) -> 1 | Q7: =IF(P7=100%,"SELESAI","BELUM") -> SELESAI | T7: TRUE | U7: ALMAHYRA DIAN KURNIA | W7: WP142026024886 | X7: TRUE | Y7: 07 POP_1BKL002_BANGKALAN GI SHELTER PLN - tahap1.docx
A8: 8 | B8: POP-B | C8: POP_1BYW005_BANYUWANGI GI SHELTER PLN | D8: POP_1BYW005 | E8: JEMBER | F8: JEMBER | G8: -8.18938261132643, 114.355989527729 | H8: BANYUWANGI | I8: PT. TRI PUTRA TRANSINDO | J8: 46048 | K8: 46217 | P8: =IF(B8="POP-SB",COUNTA(J8:M8)/4, IF(B8="POP-B",COUNTA(J8:M8)/2, COUNTA(J8:M8)/1)) -> 1 | Q8: =IF(P8=100%,"SELESAI","BELUM") -> SELESAI | T8: TRUE | U8: TRI PUTRA TRANSINDO | W8: WP142026014022 WP142026072387 | X8: FALSE
A9: 9 | B9: POP-B | C9: POP_1SBY012_DARMO GRAND GI SHELTER PLN | D9: POP_1SBY012 | E9: SURABAYA | F9: SURABAYA | G9: -7.28820411475084, 112.674534159468 | H9: SURABAYA | I9: PT. ALMAHYRA DIAN KURNIA | J9: 46114 | K9: 46234 | P9: =IF(B9="POP-SB",COUNTA(J9:M9)/4, IF(B9="POP-B",COUNTA(J9:M9)/2, COUNTA(J9:M9)/1)) -> 1 | Q9: =IF(P9=100%,"SELESAI","BELUM") -> SELESAI | T9: TRUE | U9: ALMAHYRA DIAN KURNIA | W9: WP142026040326 | X9: FALSE
A10: 10 | B10: POP-B | C10: POP_1SBY011_DISJATIM PLN | D10: POP_1SBY011 | E10: SURABAYA | F10: SURABAYA | G10: -7.26523576444187, 112.743344169396 | H10: SURABAYA | I10: PT. ALMAHYRA DIAN KURNIA | J10: 46148 | K10: 46209 | P10: =IF(B10="POP-SB",COUNTA(J10:M10)/4, IF(B10="POP-B",COUNTA(J10:M10)/2, COUNTA(J10:M10)/1)) -> 1 | Q10: =IF(P10=100%,"SELESAI","BELUM") -> SELESAI | T10: TRUE | U10: ALMAHYRA DIAN KURNIA | W10: WP142026050706 WP142026070917 | X10: TRUE | Y10: PM FOT POP DISJATIM.docx
A11: 11 | B11: POP-B | C11: POP_1PSN003_GONDANGWETAN GI SHELTER PLN | D11: POP_1PSN003 | E11: MALANG | F11: MALANG | G11: -7.69585127536913, 112.877746109631 | H11: PROBOLINGGO | I11: PT. TRI PUTRA TRANSINDO | J11: 46030 | K11: 46231 | P11: =IF(B11="POP-SB",COUNTA(J11:M11)/4, IF(B11="POP-B",COUNTA(J11:M11)/2, COUNTA(J11:M11)/1)) -> 1 | Q11: =IF(P11=100%,"SELESAI","BELUM") -> SELESAI | T11: TRUE | U11: ADYWIANSA | W11: WP142026031388 WP142026075071 | X11: FALSE
A12: 12 | B12: POP-B | C12: POP_1PSR001_GRATI GITET PLC PLN | D12: POP_1PSR001 | E12: MALANG | F12: MALANG | G12: -7.65312662130207, 113.022370817066 | H12: PROBOLINGGO | I12: PT. TRI PUTRA TRANSINDO | J12: 46031 | K12: 46267 | P12: =IF(B12="POP-SB",COUNTA(J12:M12)/4, IF(B12="POP-B",COUNTA(J12:M12)/2, COUNTA(J12:M12)/1)) -> 1 | Q12: =IF(P12=100%,"SELESAI","BELUM") -> SELESAI | T12: TRUE | U12: ADYWIANSA | W12: WP142026011392,WP142026090727 | X12: TRUE | Y12: PM FOT POP_1PSR001_GRATI GITET PLC PLN (WP142026011392).pdf
A13: 13 | B13: POP-B | C13: POP_1GSK002_GRESIK GITET PLC PLN | D13: POP_1GSK002 | E13: SURABAYA | F13: SURABAYA | G13: -7.16564571238592, 112.66003806429 | H13: GRESIK | I13: PT. GERBANG SINERGI PRIMA | J13: 46141 | K13: 46280 | P13: =IF(B13="POP-SB",COUNTA(J13:M13)/4, IF(B13="POP-B",COUNTA(J13:M13)/2, COUNTA(J13:M13)/1)) -> 1 | Q13: =IF(P13=100%,"SELESAI","BELUM") -> SELESAI | T13: TRUE | U13: ADYWIANSA | W13: WP142026045196 | X13: TRUE | Y13: WP142026045196 POP_1GSK002_GRESIK GITET PLC PLN.pdf
A14: 14 | B14: POP-B | C14: POP_1JMR001_JEMBER GI SHELTER PLN | D14: POP_1JMR001 | E14: JEMBER | F14: JEMBER | G14: -8.191963716419872, 113.69847235453312 | H14: JEMBER | I14: PT. TRI PUTRA TRANSINDO | J14: 46050 | K14: 46199 | P14: =IF(B14="POP-SB",COUNTA(J14:M14)/4, IF(B14="POP-B",COUNTA(J14:M14)/2, COUNTA(J14:M14)/1)) -> 1 | Q14: =IF(P14=100%,"SELESAI","BELUM") -> SELESAI | T14: TRUE | U14: TRI PUTRA TRANSINDO | W14: WP142026064371 | X14: FALSE
A15: 15 | B15: POP-B | C15: POP_1MLG009 KEBON AGUNG GI SHELTER PLN | D15: POP_1MLG009 | E15: MALANG | F15: MALANG | G15: -8.02207237310042, 112.61757546558 | H15: MALANG | I15: PT. GERBANG SINERGI PRIMA | J15: 46085 | K15: 46120 | P15: =IF(B15="POP-SB",COUNTA(J15:M15)/4, IF(B15="POP-B",COUNTA(J15:M15)/2, COUNTA(J15:M15)/1)) -> 1 | Q15: =IF(P15=100%,"SELESAI","BELUM") -> SELESAI | T15: TRUE | U15: ADYWIANSA | W15: WP142026030538 | X15: TRUE | Y15: PM SHELTER GI KEBON AGUNG(WP142026030538) 04-03-2026.pdf
A16: 16 | B16: POP-B | C16: POP_1MJK001_KRIAN GITET SHELTER PLN | D16: POP_1MJK001 | E16: SURABAYA | F16: SURABAYA | G16: -7.34595063753409, 112.60352891752 | H16: GRESIK | I16: PT. GERBANG SINERGI PRIMA | J16: 46126 | K16: 46204 | P16: =IF(B16="POP-SB",COUNTA(J16:M16)/4, IF(B16="POP-B",COUNTA(J16:M16)/2, COUNTA(J16:M16)/1)) -> 1 | Q16: =IF(P16=100%,"SELESAI","BELUM") -> SELESAI | T16: TRUE | U16: GERBANG SINERGI PRIMA | W16: WP142026042354 WP142026070178 | X16: TRUE | Y16: BA PM POP_PM FOT POP_1MJK001_KRIAN GITET SHELTER PLN_260414.docx
A17: 17 | B17: POP-B | C17: POP_1KPN016_LAWANG GI SHELTER PLN | D17: POP_1KPN016 | E17: MALANG | F17: MALANG | G17: -7.84958698561258, 112.690446737398 | H17: MALANG | I17: PT. GERBANG SINERGI PRIMA | J17: 46092 | K17: 46204 | P17: =IF(B17="POP-SB",COUNTA(J17:M17)/4, IF(B17="POP-B",COUNTA(J17:M17)/2, COUNTA(J17:M17)/1)) -> 1 | Q17: =IF(P17=100%,"SELESAI","BELUM") -> SELESAI | T17: TRUE | U17: ADYWIANSA | W17: WP142026031840 WP142026070173 | X17: TRUE | Y17: BA PM POP_WP142026060957 PM FOT POP_1KPN016_LAWANG GI SHELTER PLN_260606.docx
A18: 18 | B18: POP-B | C18: POP_1LMJ001_LUMAJANG GI SHELTER PLN | D18: POP_1LMJ001 | E18: JEMBER | F18: JEMBER | G18: -8.12855283840885, 113.21326728596 | H18: JEMBER | I18: PT. TRI PUTRA TRANSINDO | J18: 46083 | K18: 46217 | P18: =IF(B18="POP-SB",COUNTA(J18:M18)/4, IF(B18="POP-B",COUNTA(J18:M18)/2, COUNTA(J18:M18)/1)) -> 1 | Q18: SELESAI | T18: TRUE | U18: ADYWIANSA | W18: WP142026030244 WP142026063202 WP142026072561 | X18: TRUE | Y18: WP142026030244 POP_1LMJ001_LUMAJANG GI SHELTER PLN.pdf
A19: 19 | B19: POP-B | C19: POP_1MAD004_MANISREJO GI SHELTER PLN | D19: POP_1MAD004 | E19: MADIUN | F19: MADIUN | G19: -7.64053456465714, 111.547617405501 | H19: MADIUN | I19: PT. CIPTA KARYA TEKNOLOGI | J19: 46129 | K19: 46220 | P19: =IF(B19="POP-SB",COUNTA(J19:M19)/4, IF(B19="POP-B",COUNTA(J19:M19)/2, COUNTA(J19:M19)/1)) -> 1 | Q19: =IF(P19=100%,"SELESAI","BELUM") -> SELESAI | T19: TRUE | U19: CIPTA KARYA TEKNOLOGI | W19: WP142026042809 WP142026073262 | X19: TRUE | Y19: PM POP 17 APRIL 2026 WP142026042809 PM FOT POP SHELTER GI MANISREJO.docx
A20: 20 | B20: POP-B | C20: POP_1JBG001_MOJOAGUNG GI SHELTER PLN | D20: POP_1JBG001 | E20: SURABAYA | F20: SURABAYA | G20: -7.59111295221603, 112.344126177698 | H20: MOJOKERTO | I20: PT. INFRATECH INDONESIA | J20: 46127 | K20: 46218 | P20: =IF(B20="POP-SB",COUNTA(J20:M20)/4, IF(B20="POP-B",COUNTA(J20:M20)/2, COUNTA(J20:M20)/1)) -> 1 | Q20: =IF(P20=100%,"SELESAI","BELUM") -> SELESAI | S20: Genset gagal nyala | T20: TRUE | U20: ADYWIANSA | W20: WP142026042565 | X20: TRUE | Y20: WP142026042565 PM FOT POP_ Icon+ GI Mojoagung Shelter.pdf
A21: 21 | B21: POP-B | C21: POP_1KRS001_PAITON GITET GI SHELTER PLN | D21: POP_1KRS001 | E21: JEMBER | F21: JEMBER | G21: -7.71826038025601, 113.582425391645 | H21: PROBOLINGGO | I21: PT. TRI PUTRA TRANSINDO | J21: 46123 | K21: 46216 | P21: =IF(B21="POP-SB",COUNTA(J21:M21)/4, IF(B21="POP-B",COUNTA(J21:M21)/2, COUNTA(J21:M21)/1)) -> 1 | Q21: =IF(P21=100%,"SELESAI","BELUM") -> SELESAI | T21: TRUE | U21: TRI PUTRA TRANSINDO | W21: WP142026041879 WP142026072321 | X21: FALSE
A22: 22 | B22: POP-B | C22: POP_1KRS002_PAITON GITET PLC PLN | D22: POP_1KRS002 | E22: JEMBER | F22: JEMBER | G22: -7.71837732823069, 113.582560797282 | H22: PROBOLINGGO | I22: PT. TRI PUTRA TRANSINDO | J22: 46123 | K22: 46276 | P22: =IF(B22="POP-SB",COUNTA(J22:M22)/4, IF(B22="POP-B",COUNTA(J22:M22)/2, COUNTA(J22:M22)/1)) -> 1 | Q22: =IF(P22=100%,"SELESAI","BELUM") -> SELESAI | T22: TRUE | U22: TRI PUTRA TRANSINDO | W22: WP142026041881 | X22: TRUE | Y22: WP142026041881_Form PM POP & OLT 2026_PM FOT POP_1KRS1002_PAITON GITET PLC PLN.pdf
A23: 23 | B23: POP-B | C23: POP_1PSR003_PASURUAN REPEATER SHELTER | D23: POP_1PSR003 | E23: MALANG | F23: MALANG | G23: -7.71017314638354, 112.818167005142 | H23: PROBOLINGGO | I23: PT. TRI PUTRA TRANSINDO | J23: 46124 | K23: 46279 | P23: =IF(B23="POP-SB",COUNTA(J23:M23)/4, IF(B23="POP-B",COUNTA(J23:M23)/2, COUNTA(J23:M23)/1)) -> 1 | Q23: =IF(P23=100%,"SELESAI","BELUM") -> SELESAI | T23: TRUE | U23: INTERNAL KP MALANG | W23: INTERNAL | X23: FALSE
A24: 24 | B24: POP-B | C24: POP_1PBL001_PROBOLINGGO GI SHELTER PLN | D24: POP_1PBL001 | E24: JEMBER | F24: JEMBER | G24: -7.76396238970593, 113.213452543861 | H24: PROBOLINGGO | I24: PT. TRI PUTRA TRANSINDO | J24: 46048 | K24: 46126 | P24: =IF(B24="POP-SB",COUNTA(J24:M24)/4, IF(B24="POP-B",COUNTA(J24:M24)/2, COUNTA(J24:M24)/1)) -> 1 | Q24: =IF(P24=100%,"SELESAI","BELUM") -> SELESAI | T24: TRUE | U24: TRI PUTRA TRANSINDO | V24: PRBKNG-TPT-MBL01_SUCIANTO | W24: WP142026014270 | X24: TRUE | Y24: WP142026024869 PM FOT SHELTER GI PROBOLINGGO.pdf
A25: 25 | B25: POP-B | C25: POP_1SBY023 RUNGKUT GI SHELTER PLN | D25: POP_1SBY023 | E25: SURABAYA | F25: SURABAYA | G25: -7.34147699998977, 112.747114 | H25: SURABAYA | I25: PT. ALMAHYRA DIAN KURNIA | J25: 46148 | K25: 46242 | P25: =IF(B25="POP-SB",COUNTA(J25:M25)/4, IF(B25="POP-B",COUNTA(J25:M25)/2, COUNTA(J25:M25)/1)) -> 1 | Q25: =IF(P25=100%,"SELESAI","BELUM") -> SELESAI | T25: TRUE | U25: INTERNAL KP SURABAYA | W25: INTERNAL | X25: FALSE
A26: 26 | B26: POP-B | C26: POP_1SBY020_SAWAHAN GI SHELTER PLN | D26: POP_1SBY020 | E26: SURABAYA | F26: SURABAYA | G26: -7.25497934045857, 112.712825326868 | H26: SURABAYA | I26: PT. ALMAHYRA DIAN KURNIA | J26: 46149 | K26: 46234 | P26: =IF(B26="POP-SB",COUNTA(J26:M26)/4, IF(B26="POP-B",COUNTA(J26:M26)/2, COUNTA(J26:M26)/1)) -> 1 | Q26: =IF(P26=100%,"SELESAI","BELUM") -> SELESAI | S26: Bocor Pipa BBM | T26: TRUE | U26: ALMAHYRA DIAN KURNIA | X26: TRUE | Y26: PM FOT POP Shelter Sawahan.docx
A27: 27 | B27: POP-B | C27: POP_1SIT001_SITUBONDO GI SHELTER PLN | D27: POP_1SIT001 | E27: JEMBER | F27: JEMBER | G27: -7.71743925283533, 114.01820809892224 | H27: SITUBONDO | I27: PT. TRI PUTRA TRANSINDO | J27: 46036 | K27: 46227 | P27: =IF(B27="POP-SB",COUNTA(J27:M27)/4, IF(B27="POP-B",COUNTA(J27:M27)/2, COUNTA(J27:M27)/1)) -> 1 | Q27: SELESAI | T27: TRUE | U27: TRI PUTRA TRANSINDO | W27: WP142026012085 WP142026063031 WP142026074347 | X27: TRUE | Y27: WP142026054063 POP_1SIT001_SITUBONDO GI SHELTER PLN.pdf
A28: 28 | B28: POP-B | C28: POP_1TLG001_TULUNGAGUNG GI SHELTER PLN | D28: POP_1TLG001 | E28: MADIUN | F28: MADIUN | G28: -8.05891094083723, 111.916788237733 | H28: TRENGGALEK | I28: PT. CIPTA KARYA TEKNOLOGI | J28: 46134 | K28: 46195 | P28: =IF(B28="POP-SB",COUNTA(J28:M28)/4, IF(B28="POP-B",COUNTA(J28:M28)/2, COUNTA(J28:M28)/1)) -> 1 | Q28: =IF(P28=100%,"SELESAI","BELUM") -> SELESAI | T28: TRUE | U28: CIPTA KARYA TEKNOLOGI | W28: WP142026043736 WP142026063529 | X28: TRUE | Y28: 22 JUNI PM FOT POP_1TLG00001_GI Shelter Tulungagung.docx
A29: 29 | B29: POP-D | C29: POP_1PSR005_UDIKLAT PANDAAN PLN | D29: POP_1PSR005 | E29: MALANG | F29: MALANG | G29: -7.679876113400412, 112.7053129385984 | H29: MALANG | I29: PT. GERBANG SINERGI PRIMA | J29: 46125 | P29: =IF(B29="POP-SB",COUNTA(J29:M29)/4, IF(B29="POP-B",COUNTA(J29:M29)/2, COUNTA(J29:M29)/1)) -> 1 | Q29: =IF(P29=100%,"SELESAI","BELUM") -> SELESAI | T29: TRUE | U29: ADYWIANSA | W29: WP142026042141 | X29: TRUE | Y29: WP142026042141 PM FOT POP_1PSR005 UDIKLAT PANDAAN.pdf
A30: 30 | B30: POP-B | C30: POP_1SDA001_WARU GI ACC PLN | D30: POP_1SDA001 | E30: SURABAYA | F30: SURABAYA | G30: -7.34851444754683, 112.707373083004 | H30: SIDOARJO | I30: PT. ALMAHYRA DIAN KURNIA | J30: 46149 | K30: 46177 | L30: 46280 | P30: =IF(B30="POP-SB",COUNTA(J30:M30)/4, IF(B30="POP-B",COUNTA(J30:M30)/2, COUNTA(J30:M30)/1)) -> 1.5 | Q30: SELESAI | T30: TRUE | U30: ALMAHYRA DIAN KURNIA | W30: WP142026060708 | X30: TRUE | Y30: PM FOT Waru GI ACC.pdf
A31: 31 | B31: POP-B | C31: POP_1SDA004_WARU GI SHELTER-02 PLN | D31: POP_1SDA004 | E31: SURABAYA | F31: SURABAYA | G31: -7.347449162080058, 112.70736514072611 | H31: SIDOARJO | I31: PT. ALMAHYRA DIAN KURNIA | J31: 46149 | K31: 46247 | P31: =IF(B31="POP-SB",COUNTA(J31:M31)/4, IF(B31="POP-B",COUNTA(J31:M31)/2, COUNTA(J31:M31)/1)) -> 1 | Q31: =IF(P31=100%,"SELESAI","BELUM") -> SELESAI | T31: TRUE | U31: ALMAHYRA DIAN KURNIA | W31: WP142026050940 | X31: TRUE | Y31: PM FOT POP Shelter 2 GI Waru.docx
A32: 32 | B32: POP-B | C32: POP_1SDA10027_WARU GI SHELTER-3 PLN | D32: POP_1SDA10027 | E32: SURABAYA | F32: SURABAYA | G32: -7.34743717511337, 112.70729835832864 | H32: SIDOARJO | I32: PT. ALMAHYRA DIAN KURNIA | J32: 46149 | K32: 46279 | P32: =IF(B32="POP-SB",COUNTA(J32:M32)/4, IF(B32="POP-B",COUNTA(J32:M32)/2, COUNTA(J32:M32)/1)) -> 1 | Q32: =IF(P32=100%,"SELESAI","BELUM") -> SELESAI | T32: TRUE | U32: ALMAHYRA DIAN KURNIA | W32: WP142026050950 | X32: TRUE | Y32: PM FOT POP Shelter 3 GI Waru.docx
A33: 33 | B33: POP-B | C33: POP_1SDA10124_WARU GI SHELTER-4 PLN | D33: POP_1SDA10124 | E33: SURABAYA | F33: SURABAYA | G33: -7.347419101355969, 112.70725252149515 | H33: SIDOARJO | I33: PT. ALMAHYRA DIAN KURNIA | J33: 46149 | K33: 46177 | P33: =IF(B33="POP-SB",COUNTA(J33:M33)/4, IF(B33="POP-B",COUNTA(J33:M33)/2, COUNTA(J33:M33)/1)) -> 1 | Q33: =IF(P33=100%,"SELESAI","BELUM") -> SELESAI | T33: TRUE | U33: ALMAHYRA DIAN KURNIA | W33: WP142026060718 | X33: TRUE | Y33: PM FOT POP_1SDA10124_WARU GI SHELTER-4 PLN.pdf
A34: 34 | B34: POP-B | C34: POP_1KNR002_WLINGI GI SHELTER PLN | D34: POP_1KNR002 | E34: MALANG | F34: MALANG | G34: -8.14288656849707, 112.246691111841 | H34: MALANG | I34: PT. GERBANG SINERGI PRIMA | J34: 46126 | K34: 46179 | P34: =IF(B34="POP-SB",COUNTA(J34:M34)/4, IF(B34="POP-B",COUNTA(J34:M34)/2, COUNTA(J34:M34)/1)) -> 1 | Q34: =IF(P34=100%,"SELESAI","BELUM") -> SELESAI | T34: TRUE | U34: ADYWIANSA | W34: WP142026042329 WP142026060960 | X34: TRUE | Y34: BA PM POP_WP142026060960 PM FOT POP_1KNR002 WLINGI GI SHELTER PLN_260606.docx
A35: 35 | B35: POP-D | C35: POP_1JMR10000_POP_1JMR008_AMBULU ULP MINI ODC PLN | D35: POP_1JMR10000 | E35: JEMBER | F35: JEMBER | G35: -8.344493289800726, 113.59735164693292 | H35: JEMBER | I35: PT. TRI PUTRA TRANSINDO | J35: 46143 | P35: =IF(B35="POP-SB",COUNTA(J35:M35)/4, IF(B35="POP-B",COUNTA(J35:M35)/2, COUNTA(J35:M35)/1)) -> 1 | Q35: =IF(P35=100%,"SELESAI","BELUM") -> SELESAI | T35: TRUE | U35: TRI PUTRA TRANSINDO | W35: WP142026050030 | X35: FALSE
A36: 36 | B36: POP-D | C36: POP_1MLG013_APARTEMEN BEGAWAN MINI ODC | D36: POP_1MLG013 | E36: MALANG | F36: MALANG | G36: -7.92706601512933, 112.602552443984 | H36: MALANG | I36: PT. GERBANG SINERGI PRIMA | J36: 46113 | P36: =IF(B36="POP-SB",COUNTA(J36:M36)/4, IF(B36="POP-B",COUNTA(J36:M36)/2, COUNTA(J36:M36)/1)) -> 1 | Q36: =IF(P36=100%,"SELESAI","BELUM") -> SELESAI | T36: TRUE | U36: ADYWIANSA | W36: WP142026040180 | X36: TRUE | Y36: WP142026040180 POP_1MLG013_APARTEMEN BEGAWAN MINI ODC.pdf
A37: 37 | B37: POP-D | C37: POP_1SIT004_ASEM BAGUS ULP R12U PLN | D37: POP_1SIT004 | E37: JEMBER | F37: SURABAYA | G37: -7.71690124499754, 114.018376336153 | H37: SITUBONDO | I37: PT. TRI PUTRA TRANSINDO | J37: Dismantle | P37: =IF(B37="POP-SB",COUNTA(J37:M37)/4, IF(B37="POP-B",COUNTA(J37:M37)/2, COUNTA(J37:M37)/1)) -> 1 | Q37: =IF(P37=100%,"SELESAI","BELUM") -> SELESAI | T37: TRUE | X37: FALSE
A38: 38 | B38: POP-D | C38: POP_1SDA10006_POP_1SDA018_BABADAN GI ODC PLN | D38: POP_1SDA10006 | E38: SURABAYA | F38: SURABAYA | G38: -7.388569539245516, 112.67584013534555 | H38: SIDOARJO | I38: PT. ALMAHYRA DIAN KURNIA | P38: =IF(B38="POP-SB",COUNTA(J38:M38)/4, IF(B38="POP-B",COUNTA(J38:M38)/2, COUNTA(J38:M38)/1)) -> 0 | Q38: =IF(P38=100%,"SELESAI","BELUM") -> BELUM | T38: FALSE | X38: FALSE
A39: 39 | B39: POP-D | C39: POP_1LMG006_BABAT ULP ODC 3 PINTU PLN | D39: POP_1LMG006 | E39: SURABAYA | F39: SURABAYA | G39: -7.10029932704948, 112.192230167347 | H39: GRESIK | I39: PT. GERBANG SINERGI PRIMA | P39: =IF(B39="POP-SB",COUNTA(J39:M39)/4, IF(B39="POP-B",COUNTA(J39:M39)/2, COUNTA(J39:M39)/1)) -> 0 | Q39: =IF(P39=100%,"SELESAI","BELUM") -> BELUM | T39: FALSE | X39: FALSE
A40: 40 | B40: POP-D | C40: POP_1MJK10034_BALAI DESA SEDURI MOJOSARI ODC | D40: POP_1MJK10034 | E40: SURABAYA | F40: SURABAYA | G40: -7.513895637484539, 112.55863665812367 | H40: MOJOKERTO | I40: PT. INFRATECH INDONESIA | J40: 46119 | P40: =IF(B40="POP-SB",COUNTA(J40:M40)/4, IF(B40="POP-B",COUNTA(J40:M40)/2, COUNTA(J40:M40)/1)) -> 1 | Q40: =IF(P40=100%,"SELESAI","BELUM") -> SELESAI | T40: TRUE | U40: ADYWIANSA | W40: WP142026041222 | X40: FALSE
...

Sheet DATA MASTER
A1: REGIONAL KP | B1: KATEGORI | C1: NAMA POP | D1: HOSTNAME OLT | E1: ID POP | F1: TIPE POP | G1: POWER SUPPLY | H1: AC | I1: GENSET | J1: PM POP | K1: HEALTH INDEX (%) | L1: RESUME INDEX | M1: CATATAN PM | N1: GAMAS TERAKHIR | O1: ROOT CAUSE | P1: ACTION
A2: SURABAYA | B2: POP-SB | C2: POP_1SBY003_INTILAND LT.5 | D2: NON - OLT | E2: POP_1SBY003 | F2: RUANGAN | G2: {=IFERROR(INDEX('PM POWERSUPPLY RJBT1'!BC:BC,MATCH(E2,'PM POWERSUPPLY RJBT1'!B:B,0)),"BELUM TERDATA")} -> 100 | H2: {=IFERROR(INDEX('PM AC RJBT'!J:J,MATCH(E2,'PM AC RJBT'!A:A,0)),"NON-AC ICON")} -> 100 | I2: {=IFERROR(INDEX('PM GENSET RJBT'!AJ:AJ,MATCH(E2,'PM GENSET RJBT'!B:B,0)),"TIDAK ADA GENSET")} -> TIDAK ADA GENSET | J2: {=IFERROR(INDEX('PM POP RJBT'!P:P,MATCH(E2,'PM POP RJBT'!D:D,0)),"")*100} -> 100 | K2: =ROUND(((IF(G2="BELUM TERDATA",0,G2)*30)+(IF(H2="NON-AC ICON",100,H2)*15)+(IF(I2="TIDAK ADA GENSET",100,I2)*15)+(IF(J2="",100,J2)*40))/100,0) -> 100 | L2: =IF(K2>=80,"GOOD CONDITION",IF(K2>=60,"WARNING", IF(K2>=40,"NEED CHECK", "DANGEROUS"))) -> GOOD CONDITION
A3: SURABAYA | B3: POP-SB | C3: POP_1SDA002_WARU GI SHELTER-1 PLN | D3: NON - OLT | E3: POP_1SDA002 | F3: SHELTER | G3: {=IFERROR(INDEX('PM POWERSUPPLY RJBT1'!BC:BC,MATCH(E3,'PM POWERSUPPLY RJBT1'!B:B,0)),"BELUM TERDATA")} -> 100 | H3: {=IFERROR(INDEX('PM AC RJBT'!J:J,MATCH(E3,'PM AC RJBT'!A:A,0)),"NON-AC ICON")} -> 100 | I3: {=IFERROR(INDEX('PM GENSET RJBT'!AJ:AJ,MATCH(E3,'PM GENSET RJBT'!B:B,0)),"TIDAK ADA GENSET")} -> 60 | J3: {=IFERROR(INDEX('PM POP RJBT'!P:P,MATCH(E3,'PM POP RJBT'!D:D,0)),"")*100} -> 75 | K3: =ROUND(((IF(G3="BELUM TERDATA",0,G3)*30)+(IF(H3="NON-AC ICON",100,H3)*15)+(IF(I3="TIDAK ADA GENSET",100,I3)*15)+(IF(J3="",100,J3)*40))/100,0) -> 84 | L3: =IF(K3>=80,"GOOD CONDITION",IF(K3>=60,"WARNING", IF(K3>=40,"NEED CHECK", "DANGEROUS"))) -> GOOD CONDITION | R3: DESCRIPTION INDEX | U3: AVERAGE INDEX HEALTH PER KP
A4: MADIUN | B4: POP-B | C4: POP_1BJN001_BABAT GI SHELTER PLN | D4: NON - OLT | E4: POP_1BJN001 | F4: SHELTER | G4: {=IFERROR(INDEX('PM POWERSUPPLY RJBT1'!BC:BC,MATCH(E4,'PM POWERSUPPLY RJBT1'!B:B,0)),"BELUM TERDATA")} -> 100 | H4: {=IFERROR(INDEX('PM AC RJBT'!J:J,MATCH(E4,'PM AC RJBT'!A:A,0)),"NON-AC ICON")} -> 100 | I4: {=IFERROR(INDEX('PM GENSET RJBT'!AJ:AJ,MATCH(E4,'PM GENSET RJBT'!B:B,0)),"TIDAK ADA GENSET")} -> 100 | J4: {=IFERROR(INDEX('PM POP RJBT'!P:P,MATCH(E4,'PM POP RJBT'!D:D,0)),"")*100} -> 100 | K4: =ROUND(((IF(G4="BELUM TERDATA",0,G4)*30)+(IF(H4="NON-AC ICON",100,H4)*15)+(IF(I4="TIDAK ADA GENSET",100,I4)*15)+(IF(J4="",100,J4)*40))/100,0) -> 100 | L4: =IF(K4>=80,"GOOD CONDITION",IF(K4>=60,"WARNING", IF(K4>=40,"NEED CHECK", "DANGEROUS"))) -> GOOD CONDITION | R4: 80% - 100% | S4: GOOD CONDITION | U4: SBU | V4: =AVERAGE(K2:K875)/100 -> 0.83764302
A5: MALANG | B5: POP-B | C5: POP_1KDR10048_BANARAN GI 2 SHELTER PLN | D5: NON - OLT | E5: POP_1KDR10048 | F5: SHELTER | G5: {=IFERROR(INDEX('PM POWERSUPPLY RJBT1'!BC:BC,MATCH(E5,'PM POWERSUPPLY RJBT1'!B:B,0)),"BELUM TERDATA")} -> 100 | H5: {=IFERROR(INDEX('PM AC RJBT'!J:J,MATCH(E5,'PM AC RJBT'!A:A,0)),"NON-AC ICON")} -> 100 | I5: {=IFERROR(INDEX('PM GENSET RJBT'!AJ:AJ,MATCH(E5,'PM GENSET RJBT'!B:B,0)),"TIDAK ADA GENSET")} -> 20 | J5: {=IFERROR(INDEX('PM POP RJBT'!P:P,MATCH(E5,'PM POP RJBT'!D:D,0)),"")*100} -> 100 | K5: =ROUND(((IF(G5="BELUM TERDATA",0,G5)*30)+(IF(H5="NON-AC ICON",100,H5)*15)+(IF(I5="TIDAK ADA GENSET",100,I5)*15)+(IF(J5="",100,J5)*40))/100,0) -> 88 | L5: =IF(K5>=80,"GOOD CONDITION",IF(K5>=60,"WARNING", IF(K5>=40,"NEED CHECK", "DANGEROUS"))) -> GOOD CONDITION | R5: 60% - 79% | S5: WARNING | U5: KP MALANG | V5: =AVERAGEIF('DATA MASTER'!A:A,"MALANG",'DATA MASTER'!K:K)/100 -> 0.82355401
A6: MALANG | B6: POP-B | C6: POP_1KDR002_BANARAN GI SHELTER PLN | D6: NON - OLT | E6: POP_1KDR002 | F6: SHELTER | G6: {=IFERROR(INDEX('PM POWERSUPPLY RJBT1'!BC:BC,MATCH(E6,'PM POWERSUPPLY RJBT1'!B:B,0)),"BELUM TERDATA")} -> 100 | H6: {=IFERROR(INDEX('PM AC RJBT'!J:J,MATCH(E6,'PM AC RJBT'!A:A,0)),"NON-AC ICON")} -> 100 | I6: {=IFERROR(INDEX('PM GENSET RJBT'!AJ:AJ,MATCH(E6,'PM GENSET RJBT'!B:B,0)),"TIDAK ADA GENSET")} -> 20 | J6: {=IFERROR(INDEX('PM POP RJBT'!P:P,MATCH(E6,'PM POP RJBT'!D:D,0)),"")*100} -> 100 | K6: =ROUND(((IF(G6="BELUM TERDATA",0,G6)*30)+(IF(H6="NON-AC ICON",100,H6)*15)+(IF(I6="TIDAK ADA GENSET",100,I6)*15)+(IF(J6="",100,J6)*40))/100,0) -> 88 | L6: =IF(K6>=80,"GOOD CONDITION",IF(K6>=60,"WARNING", IF(K6>=40,"NEED CHECK", "DANGEROUS"))) -> GOOD CONDITION | R6: 40% - 59% | S6: NEED CHECK | U6: KP SURABAYA | V6: =AVERAGEIF('DATA MASTER'!A:A,"SURABAYA",'DATA MASTER'!K:K)/100 -> 0.83626198
A7: SURABAYA | B7: POP-B | C7: POP_1BKL002_BANGKALAN GI SHELTER PLN | D7: NON - OLT | E7: POP_1BKL002 | F7: SHELTER | G7: {=IFERROR(INDEX('PM POWERSUPPLY RJBT1'!BC:BC,MATCH(E7,'PM POWERSUPPLY RJBT1'!B:B,0)),"BELUM TERDATA")} -> 100 | H7: {=IFERROR(INDEX('PM AC RJBT'!J:J,MATCH(E7,'PM AC RJBT'!A:A,0)),"NON-AC ICON")} -> 100 | I7: {=IFERROR(INDEX('PM GENSET RJBT'!AJ:AJ,MATCH(E7,'PM GENSET RJBT'!B:B,0)),"TIDAK ADA GENSET")} -> 60 | J7: {=IFERROR(INDEX('PM POP RJBT'!P:P,MATCH(E7,'PM POP RJBT'!D:D,0)),"")*100} -> 100 | K7: =ROUND(((IF(G7="BELUM TERDATA",0,G7)*30)+(IF(H7="NON-AC ICON",100,H7)*15)+(IF(I7="TIDAK ADA GENSET",100,I7)*15)+(IF(J7="",100,J7)*40))/100,0) -> 94 | L7: =IF(K7>=80,"GOOD CONDITION",IF(K7>=60,"WARNING", IF(K7>=40,"NEED CHECK", "DANGEROUS"))) -> GOOD CONDITION | R7: 0% - 39% | S7: DANGEROUS | U7: KP MADIUN | V7: =AVERAGEIF('DATA MASTER'!A:A,"MADIUN",'DATA MASTER'!K:K)/100 -> 0.77006369
A8: JEMBER | B8: POP-B | C8: POP_1BYW005_BANYUWANGI GI SHELTER PLN | D8: NON - OLT | E8: POP_1BYW005 | F8: SHELTER | G8: {=IFERROR(INDEX('PM POWERSUPPLY RJBT1'!BC:BC,MATCH(E8,'PM POWERSUPPLY RJBT1'!B:B,0)),"BELUM TERDATA")} -> 100 | H8: {=IFERROR(INDEX('PM AC RJBT'!J:J,MATCH(E8,'PM AC RJBT'!A:A,0)),"NON-AC ICON")} -> 100 | I8: {=IFERROR(INDEX('PM GENSET RJBT'!AJ:AJ,MATCH(E8,'PM GENSET RJBT'!B:B,0)),"TIDAK ADA GENSET")} -> 100 | J8: {=IFERROR(INDEX('PM POP RJBT'!P:P,MATCH(E8,'PM POP RJBT'!D:D,0)),"")*100} -> 100 | K8: =ROUND(((IF(G8="BELUM TERDATA",0,G8)*30)+(IF(H8="NON-AC ICON",100,H8)*15)+(IF(I8="TIDAK ADA GENSET",100,I8)*15)+(IF(J8="",100,J8)*40))/100,0) -> 100 | L8: =IF(K8>=80,"GOOD CONDITION",IF(K8>=60,"WARNING", IF(K8>=40,"NEED CHECK", "DANGEROUS"))) -> GOOD CONDITION | U8: KP JEMBER | V8: =AVERAGEIF('DATA MASTER'!A:A,"JEMBER",'DATA MASTER'!K:K)/100 -> 0.9665812
A9: SURABAYA | B9: POP-B | C9: POP_1SBY012_DARMO GRAND GI SHELTER PLN | D9: NON - OLT | E9: POP_1SBY012 | F9: SHELTER | G9: {=IFERROR(INDEX('PM POWERSUPPLY RJBT1'!BC:BC,MATCH(E9,'PM POWERSUPPLY RJBT1'!B:B,0)),"BELUM TERDATA")} -> 100 | H9: {=IFERROR(INDEX('PM AC RJBT'!J:J,MATCH(E9,'PM AC RJBT'!A:A,0)),"NON-AC ICON")} -> NON-AC ICON | I9: {=IFERROR(INDEX('PM GENSET RJBT'!AJ:AJ,MATCH(E9,'PM GENSET RJBT'!B:B,0)),"TIDAK ADA GENSET")} -> 100 | J9: {=IFERROR(INDEX('PM POP RJBT'!P:P,MATCH(E9,'PM POP RJBT'!D:D,0)),"")*100} -> 100 | K9: =ROUND(((IF(G9="BELUM TERDATA",0,G9)*30)+(IF(H9="NON-AC ICON",100,H9)*15)+(IF(I9="TIDAK ADA GENSET",100,I9)*15)+(IF(J9="",100,J9)*40))/100,0) -> 100 | L9: =IF(K9>=80,"GOOD CONDITION",IF(K9>=60,"WARNING", IF(K9>=40,"NEED CHECK", "DANGEROUS"))) -> GOOD CONDITION | R9: RESUME INDEX
A10: SURABAYA | B10: POP-B | C10: POP_1SBY011_DISJATIM PLN | D10: NON - OLT | E10: POP_1SBY011 | F10: RUANGAN | G10: {=IFERROR(INDEX('PM POWERSUPPLY RJBT1'!BC:BC,MATCH(E10,'PM POWERSUPPLY RJBT1'!B:B,0)),"BELUM TERDATA")} -> 100 | H10: {=IFERROR(INDEX('PM AC RJBT'!J:J,MATCH(E10,'PM AC RJBT'!A:A,0)),"NON-AC ICON")} -> 100 | I10: {=IFERROR(INDEX('PM GENSET RJBT'!AJ:AJ,MATCH(E10,'PM GENSET RJBT'!B:B,0)),"TIDAK ADA GENSET")} -> 100 | J10: {=IFERROR(INDEX('PM POP RJBT'!P:P,MATCH(E10,'PM POP RJBT'!D:D,0)),"")*100} -> 100 | K10: =ROUND(((IF(G10="BELUM TERDATA",0,G10)*30)+(IF(H10="NON-AC ICON",100,H10)*15)+(IF(I10="TIDAK ADA GENSET",100,I10)*15)+(IF(J10="",100,J10)*40))/100,0) -> 100 | L10: =IF(K10>=80,"GOOD CONDITION",IF(K10>=60,"WARNING", IF(K10>=40,"NEED CHECK", "DANGEROUS"))) -> GOOD CONDITION | R10: =COUNTIFS(K2:K876,">=80",K2:K876,"<=100") -> 516 | S10: GOOD CONDITION
A11: MALANG | B11: POP-B | C11: POP_1PSN003_GONDANGWETAN GI SHELTER PLN | D11: NON - OLT | E11: POP_1PSN003 | F11: SHELTER | G11: {=IFERROR(INDEX('PM POWERSUPPLY RJBT1'!BC:BC,MATCH(E11,'PM POWERSUPPLY RJBT1'!B:B,0)),"BELUM TERDATA")} -> 100 | H11: {=IFERROR(INDEX('PM AC RJBT'!J:J,MATCH(E11,'PM AC RJBT'!A:A,0)),"NON-AC ICON")} -> 100 | I11: {=IFERROR(INDEX('PM GENSET RJBT'!AJ:AJ,MATCH(E11,'PM GENSET RJBT'!B:B,0)),"TIDAK ADA GENSET")} -> 100 | J11: {=IFERROR(INDEX('PM POP RJBT'!P:P,MATCH(E11,'PM POP RJBT'!D:D,0)),"")*100} -> 100 | K11: =ROUND(((IF(G11="BELUM TERDATA",0,G11)*30)+(IF(H11="NON-AC ICON",100,H11)*15)+(IF(I11="TIDAK ADA GENSET",100,I11)*15)+(IF(J11="",100,J11)*40))/100,0) -> 100 | L11: =IF(K11>=80,"GOOD CONDITION",IF(K11>=60,"WARNING", IF(K11>=40,"NEED CHECK", "DANGEROUS"))) -> GOOD CONDITION | R11: =COUNTIFS(K2:K876,">=60",K2:K876,"<=79") -> 335 | S11: WARNING
A12: MALANG | B12: POP-B | C12: POP_1PSR001_GRATI GITET PLC PLN | D12: NON - OLT | E12: POP_1PSR001 | F12: PLC | G12: {=IFERROR(INDEX('PM POWERSUPPLY RJBT1'!BC:BC,MATCH(E12,'PM POWERSUPPLY RJBT1'!B:B,0)),"BELUM TERDATA")} -> 100 | H12: {=IFERROR(INDEX('PM AC RJBT'!J:J,MATCH(E12,'PM AC RJBT'!A:A,0)),"NON-AC ICON")} -> NON-AC ICON | I12: {=IFERROR(INDEX('PM GENSET RJBT'!AJ:AJ,MATCH(E12,'PM GENSET RJBT'!B:B,0)),"TIDAK ADA GENSET")} -> TIDAK ADA GENSET | J12: {=IFERROR(INDEX('PM POP RJBT'!P:P,MATCH(E12,'PM POP RJBT'!D:D,0)),"")*100} -> 100 | K12: =ROUND(((IF(G12="BELUM TERDATA",0,G12)*30)+(IF(H12="NON-AC ICON",100,H12)*15)+(IF(I12="TIDAK ADA GENSET",100,I12)*15)+(IF(J12="",100,J12)*40))/100,0) -> 100 | L12: =IF(K12>=80,"GOOD CONDITION",IF(K12>=60,"WARNING", IF(K12>=40,"NEED CHECK", "DANGEROUS"))) -> GOOD CONDITION | R12: =COUNTIFS(K2:K876,">=40",K2:K876,"<=59") -> 2 | S12: NEED CHECK
A13: SURABAYA | B13: POP-B | C13: POP_1GSK002_GRESIK GITET PLC PLN | D13: NON - OLT | E13: POP_1GSK002 | F13: PLC | G13: {=IFERROR(INDEX('PM POWERSUPPLY RJBT1'!BC:BC,MATCH(E13,'PM POWERSUPPLY RJBT1'!B:B,0)),"BELUM TERDATA")} -> 100 | H13: {=IFERROR(INDEX('PM AC RJBT'!J:J,MATCH(E13,'PM AC RJBT'!A:A,0)),"NON-AC ICON")} -> NON-AC ICON | I13: {=IFERROR(INDEX('PM GENSET RJBT'!AJ:AJ,MATCH(E13,'PM GENSET RJBT'!B:B,0)),"TIDAK ADA GENSET")} -> 100 | J13: {=IFERROR(INDEX('PM POP RJBT'!P:P,MATCH(E13,'PM POP RJBT'!D:D,0)),"")*100} -> 100 | K13: =ROUND(((IF(G13="BELUM TERDATA",0,G13)*30)+(IF(H13="NON-AC ICON",100,H13)*15)+(IF(I13="TIDAK ADA GENSET",100,I13)*15)+(IF(J13="",100,J13)*40))/100,0) -> 100 | L13: =IF(K13>=80,"GOOD CONDITION",IF(K13>=60,"WARNING", IF(K13>=40,"NEED CHECK", "DANGEROUS"))) -> GOOD CONDITION | R13: =COUNTIFS(K2:K876,">=0",K2:K876,"<=39") -> 16 | S13: DANGEROUS
A14: JEMBER | B14: POP-B | C14: POP_1JMR001_JEMBER GI SHELTER PLN | D14: NON - OLT | E14: POP_1JMR001 | F14: SHELTER | G14: {=IFERROR(INDEX('PM POWERSUPPLY RJBT1'!BC:BC,MATCH(E14,'PM POWERSUPPLY RJBT1'!B:B,0)),"BELUM TERDATA")} -> 100 | H14: {=IFERROR(INDEX('PM AC RJBT'!J:J,MATCH(E14,'PM AC RJBT'!A:A,0)),"NON-AC ICON")} -> 100 | I14: {=IFERROR(INDEX('PM GENSET RJBT'!AJ:AJ,MATCH(E14,'PM GENSET RJBT'!B:B,0)),"TIDAK ADA GENSET")} -> TIDAK ADA GENSET | J14: {=IFERROR(INDEX('PM POP RJBT'!P:P,MATCH(E14,'PM POP RJBT'!D:D,0)),"")*100} -> 100 | K14: =ROUND(((IF(G14="BELUM TERDATA",0,G14)*30)+(IF(H14="NON-AC ICON",100,H14)*15)+(IF(I14="TIDAK ADA GENSET",100,I14)*15)+(IF(J14="",100,J14)*40))/100,0) -> 100 | L14: =IF(K14>=80,"GOOD CONDITION",IF(K14>=60,"WARNING", IF(K14>=40,"NEED CHECK", "DANGEROUS"))) -> GOOD CONDITION
A15: MALANG | B15: POP-B | C15: POP_1MLG009 KEBON AGUNG GI SHELTER PLN | D15: NON - OLT | E15: POP_1MLG009 | F15: SHELTER | G15: {=IFERROR(INDEX('PM POWERSUPPLY RJBT1'!BC:BC,MATCH(E15,'PM POWERSUPPLY RJBT1'!B:B,0)),"BELUM TERDATA")} -> 100 | H15: {=IFERROR(INDEX('PM AC RJBT'!J:J,MATCH(E15,'PM AC RJBT'!A:A,0)),"NON-AC ICON")} -> 100 | I15: {=IFERROR(INDEX('PM GENSET RJBT'!AJ:AJ,MATCH(E15,'PM GENSET RJBT'!B:B,0)),"TIDAK ADA GENSET")} -> 100 | J15: {=IFERROR(INDEX('PM POP RJBT'!P:P,MATCH(E15,'PM POP RJBT'!D:D,0)),"")*100} -> 100 | K15: =ROUND(((IF(G15="BELUM TERDATA",0,G15)*30)+(IF(H15="NON-AC ICON",100,H15)*15)+(IF(I15="TIDAK ADA GENSET",100,I15)*15)+(IF(J15="",100,J15)*40))/100,0) -> 100 | L15: =IF(K15>=80,"GOOD CONDITION",IF(K15>=60,"WARNING", IF(K15>=40,"NEED CHECK", "DANGEROUS"))) -> GOOD CONDITION
A16: SURABAYA | B16: POP-B | C16: POP_1MJK001_KRIAN GITET SHELTER PLN | D16: NON - OLT | E16: POP_1MJK001 | F16: SHELTER | G16: {=IFERROR(INDEX('PM POWERSUPPLY RJBT1'!BC:BC,MATCH(E16,'PM POWERSUPPLY RJBT1'!B:B,0)),"BELUM TERDATA")} -> 100 | H16: {=IFERROR(INDEX('PM AC RJBT'!J:J,MATCH(E16,'PM AC RJBT'!A:A,0)),"NON-AC ICON")} -> 100 | I16: {=IFERROR(INDEX('PM GENSET RJBT'!AJ:AJ,MATCH(E16,'PM GENSET RJBT'!B:B,0)),"TIDAK ADA GENSET")} -> 100 | J16: {=IFERROR(INDEX('PM POP RJBT'!P:P,MATCH(E16,'PM POP RJBT'!D:D,0)),"")*100} -> 100 | K16: =ROUND(((IF(G16="BELUM TERDATA",0,G16)*30)+(IF(H16="NON-AC ICON",100,H16)*15)+(IF(I16="TIDAK ADA GENSET",100,I16)*15)+(IF(J16="",100,J16)*40))/100,0) -> 100 | L16: =IF(K16>=80,"GOOD CONDITION",IF(K16>=60,"WARNING", IF(K16>=40,"NEED CHECK", "DANGEROUS"))) -> GOOD CONDITION
A17: MALANG | B17: POP-B | C17: POP_1KPN016_LAWANG GI SHELTER PLN | D17: NON - OLT | E17: POP_1KPN016 | F17: SHELTER | G17: {=IFERROR(INDEX('PM POWERSUPPLY RJBT1'!BC:BC,MATCH(E17,'PM POWERSUPPLY RJBT1'!B:B,0)),"BELUM TERDATA")} -> 100 | H17: {=IFERROR(INDEX('PM AC RJBT'!J:J,MATCH(E17,'PM AC RJBT'!A:A,0)),"NON-AC ICON")} -> 100 | I17: {=IFERROR(INDEX('PM GENSET RJBT'!AJ:AJ,MATCH(E17,'PM GENSET RJBT'!B:B,0)),"TIDAK ADA GENSET")} -> 100 | J17: {=IFERROR(INDEX('PM POP RJBT'!P:P,MATCH(E17,'PM POP RJBT'!D:D,0)),"")*100} -> 100 | K17: =ROUND(((IF(G17="BELUM TERDATA",0,G17)*30)+(IF(H17="NON-AC ICON",100,H17)*15)+(IF(I17="TIDAK ADA GENSET",100,I17)*15)+(IF(J17="",100,J17)*40))/100,0) -> 100 | L17: =IF(K17>=80,"GOOD CONDITION",IF(K17>=60,"WARNING", IF(K17>=40,"NEED CHECK", "DANGEROUS"))) -> GOOD CONDITION
A18: JEMBER | B18: POP-B | C18: POP_1LMJ001_LUMAJANG GI SHELTER PLN | D18: NON - OLT | E18: POP_1LMJ001 | F18: SHELTER | G18: {=IFERROR(INDEX('PM POWERSUPPLY RJBT1'!BC:BC,MATCH(E18,'PM POWERSUPPLY RJBT1'!B:B,0)),"BELUM TERDATA")} -> 100 | H18: {=IFERROR(INDEX('PM AC RJBT'!J:J,MATCH(E18,'PM AC RJBT'!A:A,0)),"NON-AC ICON")} -> 100 | I18: {=IFERROR(INDEX('PM GENSET RJBT'!AJ:AJ,MATCH(E18,'PM GENSET RJBT'!B:B,0)),"TIDAK ADA GENSET")} -> 100 | J18: {=IFERROR(INDEX('PM POP RJBT'!P:P,MATCH(E18,'PM POP RJBT'!D:D,0)),"")*100} -> 100 | K18: =ROUND(((IF(G18="BELUM TERDATA",0,G18)*30)+(IF(H18="NON-AC ICON",100,H18)*15)+(IF(I18="TIDAK ADA GENSET",100,I18)*15)+(IF(J18="",100,J18)*40))/100,0) -> 100 | L18: =IF(K18>=80,"GOOD CONDITION",IF(K18>=60,"WARNING", IF(K18>=40,"NEED CHECK", "DANGEROUS"))) -> GOOD CONDITION
A19: MADIUN | B19: POP-B | C19: POP_1MAD004_MANISREJO GI SHELTER PLN | D19: NON - OLT | E19: POP_1MAD004 | F19: SHELTER | G19: {=IFERROR(INDEX('PM POWERSUPPLY RJBT1'!BC:BC,MATCH(E19,'PM POWERSUPPLY RJBT1'!B:B,0)),"BELUM TERDATA")} -> 100 | H19: {=IFERROR(INDEX('PM AC RJBT'!J:J,MATCH(E19,'PM AC RJBT'!A:A,0)),"NON-AC ICON")} -> 100 | I19: {=IFERROR(INDEX('PM GENSET RJBT'!AJ:AJ,MATCH(E19,'PM GENSET RJBT'!B:B,0)),"TIDAK ADA GENSET")} -> 100 | J19: {=IFERROR(INDEX('PM POP RJBT'!P:P,MATCH(E19,'PM POP RJBT'!D:D,0)),"")*100} -> 100 | K19: =ROUND(((IF(G19="BELUM TERDATA",0,G19)*30)+(IF(H19="NON-AC ICON",100,H19)*15)+(IF(I19="TIDAK ADA GENSET",100,I19)*15)+(IF(J19="",100,J19)*40))/100,0) -> 100 | L19: =IF(K19>=80,"GOOD CONDITION",IF(K19>=60,"WARNING", IF(K19>=40,"NEED CHECK", "DANGEROUS"))) -> GOOD CONDITION
A20: SURABAYA | B20: POP-B | C20: POP_1JBG001_MOJOAGUNG GI SHELTER PLN | D20: NON - OLT | E20: POP_1JBG001 | F20: SHELTER | G20: {=IFERROR(INDEX('PM POWERSUPPLY RJBT1'!BC:BC,MATCH(E20,'PM POWERSUPPLY RJBT1'!B:B,0)),"BELUM TERDATA")} -> 100 | H20: {=IFERROR(INDEX('PM AC RJBT'!J:J,MATCH(E20,'PM AC RJBT'!A:A,0)),"NON-AC ICON")} -> 100 | I20: {=IFERROR(INDEX('PM GENSET RJBT'!AJ:AJ,MATCH(E20,'PM GENSET RJBT'!B:B,0)),"TIDAK ADA GENSET")} -> 100 | J20: {=IFERROR(INDEX('PM POP RJBT'!P:P,MATCH(E20,'PM POP RJBT'!D:D,0)),"")*100} -> 100 | K20: =ROUND(((IF(G20="BELUM TERDATA",0,G20)*30)+(IF(H20="NON-AC ICON",100,H20)*15)+(IF(I20="TIDAK ADA GENSET",100,I20)*15)+(IF(J20="",100,J20)*40))/100,0) -> 100 | L20: =IF(K20>=80,"GOOD CONDITION",IF(K20>=60,"WARNING", IF(K20>=40,"NEED CHECK", "DANGEROUS"))) -> GOOD CONDITION
A21: JEMBER | B21: POP-B | C21: POP_1KRS001_PAITON GITET GI SHELTER PLN | D21: NON - OLT | E21: POP_1KRS001 | F21: SHELTER | G21: {=IFERROR(INDEX('PM POWERSUPPLY RJBT1'!BC:BC,MATCH(E21,'PM POWERSUPPLY RJBT1'!B:B,0)),"BELUM TERDATA")} -> 100 | H21: {=IFERROR(INDEX('PM AC RJBT'!J:J,MATCH(E21,'PM AC RJBT'!A:A,0)),"NON-AC ICON")} -> 100 | I21: {=IFERROR(INDEX('PM GENSET RJBT'!AJ:AJ,MATCH(E21,'PM GENSET RJBT'!B:B,0)),"TIDAK ADA GENSET")} -> 100 | J21: {=IFERROR(INDEX('PM POP RJBT'!P:P,MATCH(E21,'PM POP RJBT'!D:D,0)),"")*100} -> 100 | K21: =ROUND(((IF(G21="BELUM TERDATA",0,G21)*30)+(IF(H21="NON-AC ICON",100,H21)*15)+(IF(I21="TIDAK ADA GENSET",100,I21)*15)+(IF(J21="",100,J21)*40))/100,0) -> 100 | L21: =IF(K21>=80,"GOOD CONDITION",IF(K21>=60,"WARNING", IF(K21>=40,"NEED CHECK", "DANGEROUS"))) -> GOOD CONDITION
A22: JEMBER | B22: POP-B | C22: POP_1KRS002_PAITON GITET PLC PLN | D22: NON - OLT | E22: POP_1KRS002 | F22: PLC | G22: {=IFERROR(INDEX('PM POWERSUPPLY RJBT1'!BC:BC,MATCH(E22,'PM POWERSUPPLY RJBT1'!B:B,0)),"BELUM TERDATA")} -> 100 | H22: {=IFERROR(INDEX('PM AC RJBT'!J:J,MATCH(E22,'PM AC RJBT'!A:A,0)),"NON-AC ICON")} -> NON-AC ICON | I22: {=IFERROR(INDEX('PM GENSET RJBT'!AJ:AJ,MATCH(E22,'PM GENSET RJBT'!B:B,0)),"TIDAK ADA GENSET")} -> TIDAK ADA GENSET | J22: {=IFERROR(INDEX('PM POP RJBT'!P:P,MATCH(E22,'PM POP RJBT'!D:D,0)),"")*100} -> 100 | K22: =ROUND(((IF(G22="BELUM TERDATA",0,G22)*30)+(IF(H22="NON-AC ICON",100,H22)*15)+(IF(I22="TIDAK ADA GENSET",100,I22)*15)+(IF(J22="",100,J22)*40))/100,0) -> 100 | L22: =IF(K22>=80,"GOOD CONDITION",IF(K22>=60,"WARNING", IF(K22>=40,"NEED CHECK", "DANGEROUS"))) -> GOOD CONDITION
A23: MALANG | B23: POP-B | C23: POP_1PSR003_PASURUAN REPEATER SHELTER | D23: NON - OLT | E23: POP_1PSR003 | F23: SHELTER | G23: {=IFERROR(INDEX('PM POWERSUPPLY RJBT1'!BC:BC,MATCH(E23,'PM POWERSUPPLY RJBT1'!B:B,0)),"BELUM TERDATA")} -> 100 | H23: {=IFERROR(INDEX('PM AC RJBT'!J:J,MATCH(E23,'PM AC RJBT'!A:A,0)),"NON-AC ICON")} -> 100 | I23: {=IFERROR(INDEX('PM GENSET RJBT'!AJ:AJ,MATCH(E23,'PM GENSET RJBT'!B:B,0)),"TIDAK ADA GENSET")} -> TIDAK ADA GENSET | J23: {=IFERROR(INDEX('PM POP RJBT'!P:P,MATCH(E23,'PM POP RJBT'!D:D,0)),"")*100} -> 100 | K23: =ROUND(((IF(G23="BELUM TERDATA",0,G23)*30)+(IF(H23="NON-AC ICON",100,H23)*15)+(IF(I23="TIDAK ADA GENSET",100,I23)*15)+(IF(J23="",100,J23)*40))/100,0) -> 100 | L23: =IF(K23>=80,"GOOD CONDITION",IF(K23>=60,"WARNING", IF(K23>=40,"NEED CHECK", "DANGEROUS"))) -> GOOD CONDITION
A24: JEMBER | B24: POP-B | C24: POP_1PBL001_PROBOLINGGO GI SHELTER PLN | D24: NON - OLT | E24: POP_1PBL001 | F24: SHELTER | G24: {=IFERROR(INDEX('PM POWERSUPPLY RJBT1'!BC:BC,MATCH(E24,'PM POWERSUPPLY RJBT1'!B:B,0)),"BELUM TERDATA")} -> 100 | H24: {=IFERROR(INDEX('PM AC RJBT'!J:J,MATCH(E24,'PM AC RJBT'!A:A,0)),"NON-AC ICON")} -> 100 | I24: {=IFERROR(INDEX('PM GENSET RJBT'!AJ:AJ,MATCH(E24,'PM GENSET RJBT'!B:B,0)),"TIDAK ADA GENSET")} -> 100 | J24: {=IFERROR(INDEX('PM POP RJBT'!P:P,MATCH(E24,'PM POP RJBT'!D:D,0)),"")*100} -> 100 | K24: =ROUND(((IF(G24="BELUM TERDATA",0,G24)*30)+(IF(H24="NON-AC ICON",100,H24)*15)+(IF(I24="TIDAK ADA GENSET",100,I24)*15)+(IF(J24="",100,J24)*40))/100,0) -> 100 | L24: =IF(K24>=80,"GOOD CONDITION",IF(K24>=60,"WARNING", IF(K24>=40,"NEED CHECK", "DANGEROUS"))) -> GOOD CONDITION
A25: SURABAYA | B25: POP-B | C25: POP_1SBY023 RUNGKUT GI SHELTER PLN | D25: NON - OLT | E25: POP_1SBY023 | F25: SHELTER | G25: {=IFERROR(INDEX('PM POWERSUPPLY RJBT1'!BC:BC,MATCH(E25,'PM POWERSUPPLY RJBT1'!B:B,0)),"BELUM TERDATA")} -> 100 | H25: {=IFERROR(INDEX('PM AC RJBT'!J:J,MATCH(E25,'PM AC RJBT'!A:A,0)),"NON-AC ICON")} -> 100 | I25: {=IFERROR(INDEX('PM GENSET RJBT'!AJ:AJ,MATCH(E25,'PM GENSET RJBT'!B:B,0)),"TIDAK ADA GENSET")} -> 100 | J25: {=IFERROR(INDEX('PM POP RJBT'!P:P,MATCH(E25,'PM POP RJBT'!D:D,0)),"")*100} -> 100 | K25: =ROUND(((IF(G25="BELUM TERDATA",0,G25)*30)+(IF(H25="NON-AC ICON",100,H25)*15)+(IF(I25="TIDAK ADA GENSET",100,I25)*15)+(IF(J25="",100,J25)*40))/100,0) -> 100 | L25: =IF(K25>=80,"GOOD CONDITION",IF(K25>=60,"WARNING", IF(K25>=40,"NEED CHECK", "DANGEROUS"))) -> GOOD CONDITION
... A34: MALANG | B34: POP-B | C34: POP_1KNR002_WLINGI GI SHELTER PLN | D34: NON - OLT | E34: POP_1KNR002 | F34: SHELTER | G34: {=IFERROR(INDEX('PM POWERSUPPLY RJBT1'!BC:BC,MATCH(E34,'PM POWERSUPPLY RJBT1'!B:B,0)),"BELUM TERDATA")} -> 100 | H34: {=IFERROR(INDEX('PM AC RJBT'!J:J,MATCH(E34,'PM AC RJBT'!A:A,0)),"NON-AC ICON")} -> 100 | I34: {=IFERROR(INDEX('PM GENSET RJBT'!AJ:AJ,MATCH(E34,'PM GENSET RJBT'!B:B,0)),"TIDAK ADA GENSET")} -> 100 | J34: {=IFERROR(INDEX('PM POP RJBT'!P:P,MATCH(E34,'PM POP RJBT'!D:D,0)),"")*100} -> 100 | K34: =ROUND(((IF(G34="BELUM TERDATA",0,G34)*30)+(IF(H34="NON-AC ICON",100,H34)*15)+(IF(I34="TIDAK ADA GENSET",100,I34)*15)+(IF(J34="",100,J34)*40))/100,0) -> 100 | L34: =IF(K34>=80,"GOOD CONDITION",IF(K34>=60,"WARNING", IF(K34>=40,"NEED CHECK", "DANGEROUS"))) -> GOOD CONDITION
A35: JEMBER | B35: POP-D | C35: POP_1JMR10000_POP_1JMR008_AMBULU ULP MINI ODC PLN | D35: NON - OLT | E35: POP_1JMR10000 | G35: {=IFERROR(INDEX('PM POWERSUPPLY RJBT1'!BC:BC,MATCH(E35,'PM POWERSUPPLY RJBT1'!B:B,0)),"BELUM TERDATA")} -> 100 | H35: {=IFERROR(INDEX('PM AC RJBT'!J:J,MATCH(E35,'PM AC RJBT'!A:A,0)),"NON-AC ICON")} -> 100 | I35: {=IFERROR(INDEX('PM GENSET RJBT'!AJ:AJ,MATCH(E35,'PM GENSET RJBT'!B:B,0)),"TIDAK ADA GENSET")} -> TIDAK ADA GENSET | J35: {=IFERROR(INDEX('PM POP RJBT'!P:P,MATCH(E35,'PM POP RJBT'!D:D,0)),"")*100} -> 100 | K35: =ROUND(((IF(G35="BELUM TERDATA",0,G35)*30)+(IF(H35="NON-AC ICON",100,H35)*15)+(IF(I35="TIDAK ADA GENSET",100,I35)*15)+(IF(J35="",100,J35)*40))/100,0) -> 100 | L35: =IF(K35>=80,"GOOD CONDITION",IF(K35>=60,"WARNING", IF(K35>=40,"NEED CHECK", "DANGEROUS"))) -> GOOD CONDITION
A36: MALANG | B36: POP-D | C36: POP_1MLG013_APARTEMEN BEGAWAN MINI ODC | D36: NON - OLT | E36: POP_1MLG013 | G36: {=IFERROR(INDEX('PM POWERSUPPLY RJBT1'!BC:BC,MATCH(E36,'PM POWERSUPPLY RJBT1'!B:B,0)),"BELUM TERDATA")} -> 100 | H36: {=IFERROR(INDEX('PM AC RJBT'!J:J,MATCH(E36,'PM AC RJBT'!A:A,0)),"NON-AC ICON")} -> NON-AC ICON | I36: {=IFERROR(INDEX('PM GENSET RJBT'!AJ:AJ,MATCH(E36,'PM GENSET RJBT'!B:B,0)),"TIDAK ADA GENSET")} -> TIDAK ADA GENSET | J36: {=IFERROR(INDEX('PM POP RJBT'!P:P,MATCH(E36,'PM POP RJBT'!D:D,0)),"")*100} -> 100 | K36: =ROUND(((IF(G36="BELUM TERDATA",0,G36)*30)+(IF(H36="NON-AC ICON",100,H36)*15)+(IF(I36="TIDAK ADA GENSET",100,I36)*15)+(IF(J36="",100,J36)*40))/100,0) -> 100 | L36: =IF(K36>=80,"GOOD CONDITION",IF(K36>=60,"WARNING", IF(K36>=40,"NEED CHECK", "DANGEROUS"))) -> GOOD CONDITION
A37: SURABAYA | B37: POP-D | C37: POP_1SIT004_ASEM BAGUS ULP R12U PLN | D37: NON - OLT | E37: POP_1SIT004 | F37: RUANGAN | G37: {=IFERROR(INDEX('PM POWERSUPPLY RJBT1'!BC:BC,MATCH(E37,'PM POWERSUPPLY RJBT1'!B:B,0)),"BELUM TERDATA")} -> 100 | H37: {=IFERROR(INDEX('PM AC RJBT'!J:J,MATCH(E37,'PM AC RJBT'!A:A,0)),"NON-AC ICON")} -> NON-AC ICON | I37: {=IFERROR(INDEX('PM GENSET RJBT'!AJ:AJ,MATCH(E37,'PM GENSET RJBT'!B:B,0)),"TIDAK ADA GENSET")} -> TIDAK ADA GENSET | J37: {=IFERROR(INDEX('PM POP RJBT'!P:P,MATCH(E37,'PM POP RJBT'!D:D,0)),"")*100} -> 100 | K37: =ROUND(((IF(G37="BELUM TERDATA",0,G37)*30)+(IF(H37="NON-AC ICON",100,H37)*15)+(IF(I37="TIDAK ADA GENSET",100,I37)*15)+(IF(J37="",100,J37)*40))/100,0) -> 100 | L37: =IF(K37>=80,"GOOD CONDITION",IF(K37>=60,"WARNING", IF(K37>=40,"NEED CHECK", "DANGEROUS"))) -> GOOD CONDITION
A38: SURABAYA | B38: POP-D | C38: POP_1SDA10006_POP_1SDA018_BABADAN GI ODC PLN | D38: NON - OLT | E38: POP_1SDA10006 | F38: ODC 3 PINTU | G38: {=IFERROR(INDEX('PM POWERSUPPLY RJBT1'!BC:BC,MATCH(E38,'PM POWERSUPPLY RJBT1'!B:B,0)),"BELUM TERDATA")} -> 100 | H38: {=IFERROR(INDEX('PM AC RJBT'!J:J,MATCH(E38,'PM AC RJBT'!A:A,0)),"NON-AC ICON")} -> 100 | I38: {=IFERROR(INDEX('PM GENSET RJBT'!AJ:AJ,MATCH(E38,'PM GENSET RJBT'!B:B,0)),"TIDAK ADA GENSET")} -> TIDAK ADA GENSET | J38: {=IFERROR(INDEX('PM POP RJBT'!P:P,MATCH(E38,'PM POP RJBT'!D:D,0)),"BELUM PM")*100} -> 0 | K38: =ROUND(((IF(G38="BELUM TERDATA",0,G38)*30)+(IF(H38="NON-AC ICON",100,H38)*15)+(IF(I38="TIDAK ADA GENSET",100,I38)*15)+(IF(J38="",100,J38)*40))/100,0) -> 60 | L38: =IF(K38>=80,"GOOD CONDITION",IF(K38>=60,"WARNING", IF(K38>=40,"NEED CHECK", "DANGEROUS"))) -> WARNING
A39: SURABAYA | B39: POP-D | C39: POP_1LMG006_BABAT ULP ODC 3 PINTU PLN | D39: NON - OLT | E39: POP_1LMG006 | G39: {=IFERROR(INDEX('PM POWERSUPPLY RJBT1'!BC:BC,MATCH(E39,'PM POWERSUPPLY RJBT1'!B:B,0)),"BELUM TERDATA")} -> 100 | H39: {=IFERROR(INDEX('PM AC RJBT'!J:J,MATCH(E39,'PM AC RJBT'!A:A,0)),"NON-AC ICON")} -> 100 | I39: {=IFERROR(INDEX('PM GENSET RJBT'!AJ:AJ,MATCH(E39,'PM GENSET RJBT'!B:B,0)),"TIDAK ADA GENSET")} -> TIDAK ADA GENSET | J39: {=IFERROR(INDEX('PM POP RJBT'!P:P,MATCH(E39,'PM POP RJBT'!D:D,0)),"")*100} -> 0 | K39: =ROUND(((IF(G39="BELUM TERDATA",0,G39)*30)+(IF(H39="NON-AC ICON",100,H39)*15)+(IF(I39="TIDAK ADA GENSET",100,I39)*15)+(IF(J39="",100,J39)*40))/100,0) -> 60 | L39: =IF(K39>=80,"GOOD CONDITION",IF(K39>=60,"WARNING", IF(K39>=40,"NEED CHECK", "DANGEROUS"))) -> WARNING
A40: SURABAYA | B40: POP-D | C40: POP_1MJK10034_BALAI DESA SEDURI MOJOSARI ODC | D40: NON - OLT | E40: POP_1MJK10034 | G40: {=IFERROR(INDEX('PM POWERSUPPLY RJBT1'!BC:BC,MATCH(E40,'PM POWERSUPPLY RJBT1'!B:B,0)),"BELUM TERDATA")} -> 100 | H40: {=IFERROR(INDEX('PM AC RJBT'!J:J,MATCH(E40,'PM AC RJBT'!A:A,0)),"NON-AC ICON")} -> 100 | I40: {=IFERROR(INDEX('PM GENSET RJBT'!AJ:AJ,MATCH(E40,'PM GENSET RJBT'!B:B,0)),"TIDAK ADA GENSET")} -> TIDAK ADA GENSET | J40: {=IFERROR(INDEX('PM POP RJBT'!P:P,MATCH(E40,'PM POP RJBT'!D:D,0)),"")*100} -> 100 | K40: =ROUND(((IF(G40="BELUM TERDATA",0,G40)*30)+(IF(H40="NON-AC ICON",100,H40)*15)+(IF(I40="TIDAK ADA GENSET",100,I40)*15)+(IF(J40="",100,J40)*40))/100,0) -> 100 | L40: =IF(K40>=80,"GOOD CONDITION",IF(K40>=60,"WARNING", IF(K40>=40,"NEED CHECK", "DANGEROUS"))) -> GOOD CONDITION
A41: SURABAYA | B41: POP-D | C41: POP_1SDA10121_BALONGBENDO GI ODC PLN | D41: NON - OLT | E41: POP_1SDA10121 | G41: {=IFERROR(INDEX('PM POWERSUPPLY RJBT1'!BC:BC,MATCH(E41,'PM POWERSUPPLY RJBT1'!B:B,0)),"BELUM TERDATA")} -> 100 | H41: {=IFERROR(INDEX('PM AC RJBT'!J:J,MATCH(E41,'PM AC RJBT'!A:A,0)),"NON-AC ICON")} -> 100 | I41: {=IFERROR(INDEX('PM GENSET RJBT'!AJ:AJ,MATCH(E41,'PM GENSET RJBT'!B:B,0)),"TIDAK ADA GENSET")} -> TIDAK ADA GENSET | J41: {=IFERROR(INDEX('PM POP RJBT'!P:P,MATCH(E41,'PM POP RJBT'!D:D,0)),"")*100} -> 100 | K41: =ROUND(((IF(G41="BELUM TERDATA",0,G41)*30)+(IF(H41="NON-AC ICON",100,H41)*15)+(IF(I41="TIDAK ADA GENSET",100,I41)*15)+(IF(J41="",100,J41)*40))/100,0) -> 100 | L41: =IF(K41>=80,"GOOD CONDITION",IF(K41>=60,"WARNING", IF(K41>=40,"NEED CHECK", "DANGEROUS"))) -> GOOD CONDITION
A42: MALANG | B42: POP-D | C42: POP_1KDR001_BANARAN GI PLC PLN | D42: NON - OLT | E42: POP_1KDR001 | F42: PLC | G42: {=IFERROR(INDEX('PM POWERSUPPLY RJBT1'!BC:BC,MATCH(E42,'PM POWERSUPPLY RJBT1'!B:B,0)),"BELUM TERDATA")} -> 100 | H42: {=IFERROR(INDEX('PM AC RJBT'!J:J,MATCH(E42,'PM AC RJBT'!A:A,0)),"NON-AC ICON")} -> NON-AC ICON | I42: {=IFERROR(INDEX('PM GENSET RJBT'!AJ:AJ,MATCH(E42,'PM GENSET RJBT'!B:B,0)),"TIDAK ADA GENSET")} -> TIDAK ADA GENSET | J42: {=IFERROR(INDEX('PM POP RJBT'!P:P,MATCH(E42,'PM POP RJBT'!D:D,0)),"")*100} -> 100 | K42: =ROUND(((IF(G42="BELUM TERDATA",0,G42)*30)+(IF(H42="NON-AC ICON",100,H42)*15)+(IF(I42="TIDAK ADA GENSET",100,I42)*15)+(IF(J42="",100,J42)*40))/100,0) -> 100 | L42: =IF(K42>=80,"GOOD CONDITION",IF(K42>=60,"WARNING", IF(K42>=40,"NEED CHECK", "DANGEROUS"))) -> GOOD CONDITION
A43: MALANG | B43: POP-D | C43: POP_1PSR002_BANGIL GI PLC PLN | D43: NON - OLT | E43: POP_1PSR002 | F43: PLC | G43: {=IFERROR(INDEX('PM POWERSUPPLY RJBT1'!BC:BC,MATCH(E43,'PM POWERSUPPLY RJBT1'!B:B,0)),"BELUM TERDATA")} -> 100 | H43: {=IFERROR(INDEX('PM AC RJBT'!J:J,MATCH(E43,'PM AC RJBT'!A:A,0)),"NON-AC ICON")} -> NON-AC ICON | I43: {=IFERROR(INDEX('PM GENSET RJBT'!AJ:AJ,MATCH(E43,'PM GENSET RJBT'!B:B,0)),"TIDAK ADA GENSET")} -> TIDAK ADA GENSET | J43: {=IFERROR(INDEX('PM POP RJBT'!P:P,MATCH(E43,'PM POP RJBT'!D:D,0)),"")*100} -> 0 | K43: =ROUND(((IF(G43="BELUM TERDATA",0,G43)*30)+(IF(H43="NON-AC ICON",100,H43)*15)+(IF(I43="TIDAK ADA GENSET",100,I43)*15)+(IF(J43="",100,J43)*40))/100,0) -> 60 | L43: =IF(K43>=80,"GOOD CONDITION",IF(K43>=60,"WARNING", IF(K43>=40,"NEED CHECK", "DANGEROUS"))) -> WARNING
A44: SURABAYA | B44: POP-D | C44: POP_1BKL001_BANGKALAN ULP PLN | D44: NON - OLT | E44: POP_1BKL001 | G44: {=IFERROR(INDEX('PM POWERSUPPLY RJBT1'!BC:BC,MATCH(E44,'PM POWERSUPPLY RJBT1'!B:B,0)),"BELUM TERDATA")} -> 100 | H44: {=IFERROR(INDEX('PM AC RJBT'!J:J,MATCH(E44,'PM AC RJBT'!A:A,0)),"NON-AC ICON")} -> 100 | I44: {=IFERROR(INDEX('PM GENSET RJBT'!AJ:AJ,MATCH(E44,'PM GENSET RJBT'!B:B,0)),"TIDAK ADA GENSET")} -> TIDAK ADA GENSET | J44: {=IFERROR(INDEX('PM POP RJBT'!P:P,MATCH(E44,'PM POP RJBT'!D:D,0)),"")*100} -> 0 | K44: =ROUND(((IF(G44="BELUM TERDATA",0,G44)*30)+(IF(H44="NON-AC ICON",100,H44)*15)+(IF(I44="TIDAK ADA GENSET",100,I44)*15)+(IF(J44="",100,J44)*40))/100,0) -> 60 | L44: =IF(K44>=80,"GOOD CONDITION",IF(K44>=60,"WARNING", IF(K44>=40,"NEED CHECK", "DANGEROUS"))) -> WARNING
A45: JEMBER | B45: POP-D | C45: POP_1BYW10000_BANYUWANGI UP3 ODC PLN | D45: NON - OLT | E45: POP_1BYW10000 | G45: {=IFERROR(INDEX('PM POWERSUPPLY RJBT1'!BC:BC,MATCH(E45,'PM POWERSUPPLY RJBT1'!B:B,0)),"BELUM TERDATA")} -> 100 | H45: {=IFERROR(INDEX('PM AC RJBT'!J:J,MATCH(E45,'PM AC RJBT'!A:A,0)),"NON-AC ICON")} -> 100 | I45: {=IFERROR(INDEX('PM GENSET RJBT'!AJ:AJ,MATCH(E45,'PM GENSET RJBT'!B:B,0)),"TIDAK ADA GENSET")} -> TIDAK ADA GENSET | J45: {=IFERROR(INDEX('PM POP RJBT'!P:P,MATCH(E45,'PM POP RJBT'!D:D,0)),"")*100} -> 100 | K45: =ROUND(((IF(G45="BELUM TERDATA",0,G45)*30)+(IF(H45="NON-AC ICON",100,H45)*15)+(IF(I45="TIDAK ADA GENSET",100,I45)*15)+(IF(J45="",100,J45)*40))/100,0) -> 100 | L45: =IF(K45>=80,"GOOD CONDITION",IF(K45>=60,"WARNING", IF(K45>=40,"NEED CHECK", "DANGEROUS"))) -> GOOD CONDITION
A46: JEMBER | B46: POP-D | C46: POP_1BYW003_BANYUWANGI UP3 PLN | D46: NON - OLT | E46: POP_1BYW003 | G46: {=IFERROR(INDEX('PM POWERSUPPLY RJBT1'!BC:BC,MATCH(E46,'PM POWERSUPPLY RJBT1'!B:B,0)),"BELUM TERDATA")} -> 100 | H46: {=IFERROR(INDEX('PM AC RJBT'!J:J,MATCH(E46,'PM AC RJBT'!A:A,0)),"NON-AC ICON")} -> 100 | I46: {=IFERROR(INDEX('PM GENSET RJBT'!AJ:AJ,MATCH(E46,'PM GENSET RJBT'!B:B,0)),"TIDAK ADA GENSET")} -> TIDAK ADA GENSET | J46: {=IFERROR(INDEX('PM POP RJBT'!P:P,MATCH(E46,'PM POP RJBT'!D:D,0)),"")*100} -> 100 | K46: =ROUND(((IF(G46="BELUM TERDATA",0,G46)*30)+(IF(H46="NON-AC ICON",100,H46)*15)+(IF(I46="TIDAK ADA GENSET",100,I46)*15)+(IF(J46="",100,J46)*40))/100,0) -> 100 | L46: =IF(K46>=80,"GOOD CONDITION",IF(K46>=60,"WARNING", IF(K46>=40,"NEED CHECK", "DANGEROUS"))) -> GOOD CONDITION
A47: MALANG | B47: POP-D | C47: POP_1BTU001_BATU ULP ODC-01 PLN | D47: NON - OLT | E47: POP_1BTU001 | G47: {=IFERROR(INDEX('PM POWERSUPPLY RJBT1'!BC:BC,MATCH(E47,'PM POWERSUPPLY RJBT1'!B:B,0)),"BELUM TERDATA")} -> 100 | H47: {=IFERROR(INDEX('PM AC RJBT'!J:J,MATCH(E47,'PM AC RJBT'!A:A,0)),"NON-AC ICON")} -> 100 | I47: {=IFERROR(INDEX('PM GENSET RJBT'!AJ:AJ,MATCH(E47,'PM GENSET RJBT'!B:B,0)),"TIDAK ADA GENSET")} -> TIDAK ADA GENSET | J47: {=IFERROR(INDEX('PM POP RJBT'!P:P,MATCH(E47,'PM POP RJBT'!D:D,0)),"")*100} -> 100 | K47: =ROUND(((IF(G47="BELUM TERDATA",0,G47)*30)+(IF(H47="NON-AC ICON",100,H47)*15)+(IF(I47="TIDAK ADA GENSET",100,I47)*15)+(IF(J47="",100,J47)*40))/100,0) -> 100 | L47: =IF(K47>=80,"GOOD CONDITION",IF(K47>=60,"WARNING", IF(K47>=40,"NEED CHECK", "DANGEROUS"))) -> GOOD CONDITION
A48: MALANG | B48: POP-D | C48: POP_1BTU10001_BATU ULP ODC-02 PLN | D48: NON - OLT | E48: POP_1BTU10001 | G48: {=IFERROR(INDEX('PM POWERSUPPLY RJBT1'!BC:BC,MATCH(E48,'PM POWERSUPPLY RJBT1'!B:B,0)),"BELUM TERDATA")} -> 100 | H48: {=IFERROR(INDEX('PM AC RJBT'!J:J,MATCH(E48,'PM AC RJBT'!A:A,0)),"NON-AC ICON")} -> 100 | I48: {=IFERROR(INDEX('PM GENSET RJBT'!AJ:AJ,MATCH(E48,'PM GENSET RJBT'!B:B,0)),"TIDAK ADA GENSET")} -> TIDAK ADA GENSET | J48: {=IFERROR(INDEX('PM POP RJBT'!P:P,MATCH(E48,'PM POP RJBT'!D:D,0)),"")*100} -> 100 | K48: =ROUND(((IF(G48="BELUM TERDATA",0,G48)*30)+(IF(H48="NON-AC ICON",100,H48)*15)+(IF(I48="TIDAK ADA GENSET",100,I48)*15)+(IF(J48="",100,J48)*40))/100,0) -> 100 | L48: =IF(K48>=80,"GOOD CONDITION",IF(K48>=60,"WARNING", IF(K48>=40,"NEED CHECK", "DANGEROUS"))) -> GOOD CONDITION
...

Sheet PM AC RJBT
A1: ID POP | B1: Lokasi | C1: Kategori | D1: Model | E1: pemilik | F1: note | G1: SUHU RUANGAN | H1: KONDISI AC | I1: PREVENTIVE MAINTENANCE | J1: HEALTH INDEX AC | K1: Last PM | L1: tgl PM #1 | M1: tgl PM #2 | N1: tgl PM #3 | O1: tgl PM #4 | P1: temuan | Q1: status temuan | R1: Area Servpo | S1: jadwal next PM | T1: selisih | U1: alarm | V1: need new AC | W1: ada prgkt besar | X1: thn install | Y1: jml AC | Z1: BIAYA SERVICE AC | AA1: merk AC #1 | AB1: TIpe AC #1 | AC1: kap. AC #1 | AD1: Jenis Freon AC #1 | AE1: thn manufaktur AC #1 | AF1: install date AC #1 | AG1: SN AC #1 | AH1: SUHU AC #1 | AI1: Besar Arus (A) AC # 1 | AJ1: merk AC #2 | AK1: tipe AC #2 | AL1: kap. AC #2 | AM1: Jenis Freon AC #2 | AN1: thn manufaktur AC #2 | AO1: install date AC #2 | AP1: SN AC #2 | AQ1: SUHU AC #2 | AR1: Besar Arus (A) AC # 2 | AS1: merk AC #3 | AT1: tipe AC #3 | AU1: kap. AC #3 | AV1: jenis freon AC #3 | AW1: thn manufaktur #3 | AX1: install date AC #3 | AY1: SN AC #3 | AZ1: Suhu AC # 3 | BA1: Besar Arus (A) AC #3 | BB1: merk AC #42 | BC1: tipe AC #4 | BD1: kap. AC #4 | BE1: jenis freon AC #4 | BF1: thn manufaktur #4 | BG1: install date AC #4
A2: POP_1BJN001 | B2: BABAT GI SHELTER PLN | C2: POP-B | D2: Shelter | E2: ICON+ | G2: NORMAL | H2: NORMAL | I2: NORMAL | J2: =IF(G2="NORMAL",50,0)+IF(H2="NORMAL",20,0)+IF(I2="NORMAL",30,0) -> 100 | K2: 46196 | L2: 46044 | M2: 46196 | P2: sdh lemah sudah berumur 13th | Q2: done | R2: TUBAN | S2: 21-Oct-26 | T2: 27 | W2: ya | Y2: 3 | AA2: Daikin | AB2: AC-0035-024 | AC2: 1,5 PK | AD2: R32 | AE2: 2024 | AF2: 2024 | AH2: 2,7 Derajat Celcius | AJ2: Daikin R32 | AK2: AC-0035-014 | AL2: 1.5 PK | AM2: r32 | AN2: 2014 | AO2: 2014 | AQ2: 10,2 Derajat Celcius | AR2: 6,6 Ampere | AS2: Daikin | AT2: AC-0035-025 | AU2: 1.5 PK | AV2: r32 | AW2: 2025 | AX2: 11-Aug-25 | AY2: E333942 / E345485 | AZ2: 1,1 Derajat Celcius
P3: 11aug 2025 : ganti ac 1,5pk
A4: POP_1SDA002 | B4: WARU GI SHELTER-1 PLN | C4: POP-SB | D4: Shelter | E4: ICON+ | G4: NORMAL | H4: NORMAL | I4: NORMAL | J4: =IF(G4="NORMAL",50,0)+IF(H4="NORMAL",20,0)+IF(I4="NORMAL",30,0) -> 100 | K4: 10-May-26 | L4: 46071 | M4: 10-May-26 | R4: SIDOARJO | S4: 46272 | T4: 71 | W4: ya | X4: 2022 | Y4: 4 | AA4: Daikin R22 | AC4: 1,5 PK | AJ4: Daikin R32 | AL4: 1,5 PK | AS4: Daikin | AU4: 2 PK | AX4: 44562 | BB4: Daikin | BD4: 2 PK | BG4: 44562
A5: POP_1BJN003 | B5: BOJONEGORO UP3 PLN | C5: POP-D | D5: Building | E5: ICON+ | G5: NORMAL | H5: NORMAL | I5: NORMAL | J5: =IF(G5="NORMAL",50,0)+IF(H5="NORMAL",20,0)+IF(I5="NORMAL",30,0) -> 100 | K5: 46196 | L5: 46044 | M5: 46196 | P5: 22 Jan 2026 : AC muncul es | 23 Juni 2026 : Plafon PoP Jebol | Q5: done | | R5: TUBAN | S5: 21-Oct-26 | T5: 27 | W5: YA | Y5: 1 | AA5: Daikin | AB5: AC-0050-020 | AC5: 2 pk | AD5: R32 | AE5: 2020 | AF5: 2020
A6: POP_1KDR10048 | B6: BANARAN GI 2 SHELTER PLN | C6: POP-B | D6: Shelter | E6: ICON+ | F6: Penggantian AC Baru | G6: NORMAL | H6: NORMAL | I6: NORMAL | J6: =IF(G6="NORMAL",50,0)+IF(H6="NORMAL",20,0)+IF(I6="NORMAL",30,0) -> 100 | K6: 46197 | L6: 46045 | M6: 46129 | N6: 46140 | O6: 46197 | R6: KEDIRI | S6: 22-Oct-26 | T6: 26 | W6: YA | X6: 2024 | Y6: 3 | AA6: Daikin R32 | AB6: FTC50-NV14 | AC6: 2PK | AD6: R32 | AE6: 2023 | AF6: 30-Oct-24 | AH6: 28 Apr 26 : 7,9 Derajat Celcius. 24 Jun 26 : Suhu AC 11,2 Derajat Celcius, Suhu Perangkat : 20 Derajat Celcius | AI6: 24 Jun 26 : 6,6 A | AJ6: GREE | AK6: GWC-18N1/I | AL6: 2 PK | AM6: R32 | AN6: 2025 | AO6: 46129 | AQ6: 28 Apr 26 : 9,1 Derajat Celcius. 24 Jun 26 : Suhu AC : 12,2 Derajat Celcius. Suhu Perangkat 20 Derajat Celcius. | AR6: 24 Juni 2026 :5,6 A | AS6: Daikin R32 | AT6: FTC35-NV14 | AU6: 1.5 PK | AV6: R32 | AW6: 2022 | AX6: 44814 | AZ6: 28 Apr 26 : 10,1 Derajat Celcius. 24 Jun 26 : Suhu AC : 12,3 Derajat Celcius, Suhu Perangkat : 20 ,6 Derajat Celcius. | BA6: 24 Juni 2026 : 5,0 A
A7: POP_1KDR002 | B7: BANARAN GI SHELTER PLN | C7: POP-B | D7: Shelter | E7: ICON+ | G7: NORMAL | H7: NORMAL | I7: NORMAL | J7: =IF(G7="NORMAL",50,0)+IF(H7="NORMAL",20,0)+IF(I7="NORMAL",30,0) -> 100 | K7: 46197 | L7: 46045 | M7: 46125 | N7: 46140 | O7: 46197 | R7: KEDIRI | S7: 22-Oct-26 | T7: 26 | W7: YA | Y7: 4 | AA7: Daikin R32 | AB7: FTC35-NV14 | AC7: 1.5 PK | AD7: R32 | AE7: 2022 | AF7: 44936 | AH7: 28 Apr 26 : 10,2 Derajat Celcius. 24 Jun 26 : Suhu AC 14,3 Derajat Celcius, Suhu Perangkat : 18,7 Derajat Celcius | AI7: 24 Jun 26 : 5,4 A | AJ7: Daikin R22 | AK7: FTC35-NV14 | AL7: 1.5 PK | AM7: R32 | AN7: 2012 | AO7: 30-Oct-12 | AQ7: 28 Apr 26 : 10,6 Derajat Celcius. 24 Jun 26 : Suhu AC 14,5 Derajat Celcius, Suhu Perangkat : 18 ,7 Derajat Celcius | AR7: 24 Jun 26 : 5,2 A | AS7: Daikin R32 | AT7: FTC50-NV14 | AU7: 2 PK | AV7: R32 | AW7: 2022 | AX7: 44875 | AZ7: 28 Apr 26 : 8,1 Derajat Celcius. 24 Jun 26 : Suhu AC 10,0 Derajat Celcius. Suhu Perangkat : 18 ,4 Derajat Celcius. | BA7: 24 Jun 26 : 5,7 A | BB7: Daikin R32 | BC7: FTC50-NV14 | BD7: 2 PK | BE7: R32 | BF7: 2023 | BG7: 45381
A8: POP_1PSR004 | B8: BANGIL GI SHELTER PLN | C8: POP-B | D8: Shelter | E8: ICON+ | G8: NORMAL | H8: NORMAL | I8: NORMAL | J8: =IF(G8="NORMAL",50,0)+IF(H8="NORMAL",20,0)+IF(I8="NORMAL",30,0) -> 100 | K8: 19-May-26 | L8: 46072 | M8: 19-May-26 | P8: AC inverter sering rusak sudah berumur 9th (done 22sep 2025 : replace AC) | Q8: done | R8: PROBOLINGGO | S8: 46281 | T8: 62 | W8: ya | Y8: 2 | AA8: Gree | AB8: GWC12MOO5A | AC8: 1.5 PK | AD8: R32 | AE8: 2025 | AF8: 45922 | AH8: 14,5 Derajat Celcius | AJ8: DAIKIN | AK8: FTC35-NV10 | AL8: 1.5 PK | AM8: R32 | AQ8: 17,0 Derajat Celcius
A9: POP_1BKL002 | B9: BANGKALAN GI SHELTER PLN | C9: POP-B | D9: Shelter | E9: ICON+ | G9: NORMAL | H9: NORMAL | I9: NORMAL | J9: =IF(G9="NORMAL",50,0)+IF(H9="NORMAL",20,0)+IF(I9="NORMAL",30,0) -> 100 | K9: 12-May-26 | L9: 46065 | M9: 12-May-26 | R9: MADURA | S9: 46274 | T9: 69 | W9: YA | Y9: 2 | AA9: DAIKIN | AB9: FTC35-NV14 | AC9: 1.5 PK | AD9: R32 | AE9: 2025 | AF9: 45746 | AJ9: DAIKIN | AK9: FTC35-NV14 | AL9: 1.5 PK | AM9: R32 | AN9: 2025 | AO9: 45746
A10: POP_1BYW005 | B10: BANYUWANGI GI SHELTER PLN | C10: POP-B | D10: Shelter | E10: ICON+ | F10: AC sudah lama | G10: NORMAL | H10: NORMAL | I10: NORMAL | J10: =IF(G10="NORMAL",50,0)+IF(H10="NORMAL",20,0)+IF(I10="NORMAL",30,0) -> 100 | K10: 20-May-26 | L10: 46071 | M10: 20-May-26 | R10: BANYUWANGI | S10: 46282 | T10: 61 | V10: 2PK | W10: YA | Y10: 3 | AA10: PANASONIC | AB10: AC-0050-16 / CSYN18WKJ | AC10: 2 PK | AD10: R32 | AE10: 2016 | AF10: 2016 | AH10: 12,3 Derajat Celcius | AJ10: PANASONIC | AK10: CSYN18WKJ | AL10: 2 PK | AM10: R32 | AN10: 2016 | AO10: 2016 | AQ10: 10 Derajat Celcius | AS10: DAIKIN | AT10: FTC50-NV14 | AU10: 2pk | AV10: R32 | AW10: 2024 | AX10: 2024 | AZ10: 9,9 Derajat Celcius | BB10: DAIKIN | BC10: FTC50-NV14 | BD10: 2PK | BE10: R32 | BF10: 2024 | BG10: 45763
G11: NORMAL | H11: NORMAL | I11: NORMAL | J11: =IF(G11="NORMAL",50,0)+IF(H11="NORMAL",20,0)+IF(I11="NORMAL",30,0) -> 100 | P11: 4sep : replace ac. || PM AC 2026 : AC outdoor Unit 2 Berkarat, kompresor panas karena freon kosong. Unit AC Outdoor Unit AC 1 dan 2 dilakukan penggantian (4 Mei 2026) kondisi outdoor AC berkarat.
